Traceback (most recent call last):
  File "C:\Users\mchennaboina\AppData\Roaming\Python\Python311\site-packages\urllib3\connectionpool.py", line 467, in _make_request
    self._validate_conn(conn)
  File "C:\Users\mchennaboina\AppData\Roaming\Python\Python311\site-packages\urllib3\connectionpool.py", line 1096, in _validate_conn
    conn.connect()
  File "C:\Users\mchennaboina\AppData\Roaming\Python\Python311\site-packages\urllib3\connection.py", line 642, in connect
    sock_and_verified = _ssl_wrap_socket_and_match_hostname(
                        ^^^^^^^^^^^^^^^^^^^^^^^^^^^^^^^^^^^^
  File "C:\Users\mchennaboina\AppData\Roaming\Python\Python311\site-packages\urllib3\connection.py", line 782, in _ssl_wrap_socket_and_match_hostname
    ssl_sock = ssl_wrap_socket(
               ^^^^^^^^^^^^^^^^
  File "C:\Users\mchennaboina\AppData\Roaming\Python\Python311\site-packages\urllib3\util\ssl_.py", line 470, in ssl_wrap_socket
    ssl_sock = _ssl_wrap_socket_impl(sock, context, tls_in_tls, server_hostname)
               ^^^^^^^^^^^^^^^^^^^^^^^^^^^^^^^^^^^^^^^^^^^^^^^^^^^^^^^^^^^^^^^^^
  File "C:\Users\mchennaboina\AppData\Roaming\Python\Python311\site-packages\urllib3\util\ssl_.py", line 514, in _ssl_wrap_socket_impl
    return ssl_context.wrap_socket(sock, server_hostname=server_hostname)
           ^^^^^^^^^^^^^^^^^^^^^^^^^^^^^^^^^^^^^^^^^^^^^^^^^^^^^^^^^^^^^^
  File "C:\Program Files\Python311\Lib\ssl.py", line 517, in wrap_socket
    return self.sslsocket_class._create(
           ^^^^^^^^^^^^^^^^^^^^^^^^^^^^^
  File "C:\Program Files\Python311\Lib\ssl.py", line 1075, in _create
    self.do_handshake()
  File "C:\Program Files\Python311\Lib\ssl.py", line 1346, in do_handshake
    self._sslobj.do_handshake()
ssl.SSLCertVerificationError: [SSL: CERTIFICATE_VERIFY_FAILED] certificate verify failed: unable to get local issuer certificate (_ssl.c:1002)

During handling of the above exception, another exception occurred:

Traceback (most recent call last):
  File "C:\Users\mchennaboina\AppData\Roaming\Python\Python311\site-packages\urllib3\connectionpool.py", line 790, in urlopen
    response = self._make_request(
               ^^^^^^^^^^^^^^^^^^^
  File "C:\Users\mchennaboina\AppData\Roaming\Python\Python311\site-packages\urllib3\connectionpool.py", line 491, in _make_request
    raise new_e
urllib3.exceptions.SSLError: [SSL: CERTIFICATE_VERIFY_FAILED] certificate verify failed: unable to get local issuer certificate (_ssl.c:1002)

The above exception was the direct cause of the following exception:

Traceback (most recent call last):
  File "C:\Users\mchennaboina\AppData\Roaming\Python\Python311\site-packages\requests\adapters.py", line 486, in send
    resp = conn.urlopen(
           ^^^^^^^^^^^^^
  File "C:\Users\mchennaboina\AppData\Roaming\Python\Python311\site-packages\urllib3\connectionpool.py", line 844, in urlopen
    retries = retries.increment(
              ^^^^^^^^^^^^^^^^^^
  File "C:\Users\mchennaboina\AppData\Roaming\Python\Python311\site-packages\urllib3\util\retry.py", line 515, in increment
    raise MaxRetryError(_pool, url, reason) from reason  # type: ignore[arg-type]
    ^^^^^^^^^^^^^^^^^^^^^^^^^^^^^^^^^^^^^^^^^^^^^^^^^^^
urllib3.exceptions.MaxRetryError: HTTPSConnectionPool(host='api.threatbook.io', port=443): Max retries exceeded with url: /v1/community/ip?apikey=b40fa6ce50414a719004090c4cf0cbfd1ed801e4ad5f44cb86f541e3d93478ad&resource=103.56.53.120 (Caused by SSLError(SSLCertVerificationError(1, '[SSL: CERTIFICATE_VERIFY_FAILED] certificate verify failed: unable to get local issuer certificate (_ssl.c:1002)')))

During handling of the above exception, another exception occurred:

Traceback (most recent call last):
  File "C:\Users\mchennaboina\Videos\Reputation_IP_VT_CTI_IPDB\Reputation_IP_VT_CTI_IPDB.py", line 259, in <module>
    process_excel_CTI(input_file, CTI_api_key, results)
  File "C:\Users\mchennaboina\Videos\Reputation_IP_VT_CTI_IPDB\Reputation_IP_VT_CTI_IPDB.py", line 205, in process_excel_CTI
    judgments_value, final_verdict = get_threatbook_info(CTI_api_key, ip_address)
                                     ^^^^^^^^^^^^^^^^^^^^^^^^^^^^^^^^^^^^^^^^^^^^
  File "C:\Users\mchennaboina\Videos\Reputation_IP_VT_CTI_IPDB\Reputation_IP_VT_CTI_IPDB.py", line 168, in get_threatbook_info
    response = requests.get(url, params=params, headers=headers)
               ^^^^^^^^^^^^^^^^^^^^^^^^^^^^^^^^^^^^^^^^^^^^^^^^^
  File "C:\Users\mchennaboina\AppData\Roaming\Python\Python311\site-packages\requests\api.py", line 73, in get
    return request("get", url, params=params, **kwargs)
           ^^^^^^^^^^^^^^^^^^^^^^^^^^^^^^^^^^^^^^^^^^^^
  File "C:\Users\mchennaboina\AppData\Roaming\Python\Python311\site-packages\requests\api.py", line 59, in request
    return session.request(method=method, url=url, **kwargs)
           ^^^^^^^^^^^^^^^^^^^^^^^^^^^^^^^^^^^^^^^^^^^^^^^^^
  File "C:\Users\mchennaboina\AppData\Roaming\Python\Python311\site-packages\requests\sessions.py", line 589, in request
    resp = self.send(prep, **send_kwargs)
           ^^^^^^^^^^^^^^^^^^^^^^^^^^^^^^
  File "C:\Users\mchennaboina\AppData\Roaming\Python\Python311\site-packages\requests\sessions.py", line 703, in send
    r = adapter.send(request, **kwargs)
        ^^^^^^^^^^^^^^^^^^^^^^^^^^^^^^^
  File "C:\Users\mchennaboina\AppData\Roaming\Python\Python311\site-packages\requests\adapters.py", line 517, in send
    raise SSLError(e, request=request)
requests.exceptions.SSLError: HTTPSConnectionPool(host='api.threatbook.io', port=443): Max retries exceeded with url: /v1/community/ip?apikey=b40fa6ce50414a719004090c4cf0cbfd1ed801e4ad5f44cb86f541e3d93478ad&resource=103.56.53.120 (Caused by SSLError(SSLCertVerificationError(1, '[SSL: CERTIFICATE_VERIFY_FAILED] certificate verify failed: unable to get local issuer certificate (_ssl.c:1002)')))
